#VRML_SIM R2021a utf8
PROTO ET3116A [
  field SFString name "ET3116A"
  field SFVec3f translation 0 0 0
  field SFRotation rotation 0 1 0 0
  field SFNode physics1 NULL
  field SFNode physics2 NULL
  field SFNode physics3 NULL
  field SFNode jointParameters1 HingeJointParameters { axis 0 -1 0 }
  field SFNode jointParameters2 HingeJointParameters { axis 0 0 1 }
  field MFNode device1 []
  field MFNode device2 []
  field SFBool supervisor FALSE
  field SFString controller "void"
  field MFString controllerArgs  []
  field MFNode baseExtensionSlot []
  field MFNode loadExtensionSlot []
]
{
  Robot {
    translation IS translation
    rotation IS rotation
    name IS name
    supervisor IS supervisor
    controller IS controller
    controllerArgs IS controllerArgs
    physics IS physics1
    boundingObject Transform {
      translation 0 0.35 0
      children [
        Box {
          size 0.6 0.6 0.6
        }
      ]
    }
    children [
      DEF BASE_EXTENSION_SLOT Group {
        children IS baseExtensionSlot
      }
      DEF BASE1 Transform {
        rotation -0.9999999999961744 -2.397449999990828e-09 2.7661199999894182e-06 1.5708
        children [
          Shape {
            appearance PBRAppearance {
              baseColor 0.1 0.1 0.1
              roughness 1
              metalness 0
            }
            geometry Mesh {
              url [
                "meshes/ET3116A_base1.STL"
              ]
            }
          }
        ]
      }
      DEF YAW_AXIS HingeJoint {
        jointParameters IS jointParameters1
        device IS device1
        endPoint Solid {
          translation 0 1.0510000000000006 0
          rotation 0 -1 0 0
          boundingObject Box {
            size 0.6 0.6 0.6
          }
          physics IS physics2
          children [
            DEF BASE2 Transform {
              translation 0 -1.051 0
              rotation -0.5773509358554485 0.5773509358554485 0.5773489358556708 2.0944
              children [
                Transform {
                  rotation 0 0 1 -0.05
                  children [
                    Shape {
                      appearance PBRAppearance {
                        baseColor 0.2 0.2 0.2
                        roughness 1
                        metalness 0
                        name "DefaultMaterial"
                      }
                      geometry Mesh {
                        url [
                          "meshes/ET3116A_base2.STL"
                        ]
                      }
                    }
                  ]
                }
              ]
            }
            DEF PITCH_AXIS HingeJoint {
              jointParameters IS jointParameters2
              device IS device2
              endPoint DEF LOAD Solid {
                rotation 0 0 1 0
                physics IS physics3
                children [
                  DEF LEFT_ARM Transform {
                    translation 0 0 -0.339
                    rotation 0.7071072811780902 0.7071062811776925 -4.897291947386533e-06 -3.1415853071795863
                    children [
                      Shape {
                        appearance PBRAppearance {
                          baseColor 0.8 0.8 0.8
                          roughness 1
                          metalness 0
                          name "DefaultMaterial"
                        }
                        geometry Mesh {
                          url [
                            "meshes/ET3116A_leftarm.STL"
                          ]
                        }
                      }
                      Transform {
                        translation 0 -0.42 0.5
                        rotation 1 0 0 0
                        children [
                          Shape {
                            appearance PBRAppearance {
                              baseColor 0.1 0.1 0.1
                              roughness 1
                              metalness 0
                            }
                            geometry Box {
                              size 0.45 0.01 0.4
                            }
                          }
                        ]
                      }
                      Transform {
                        translation 0 0.42 0.5
                        rotation 1 0 0 0
                        children [
                          Shape {
                            appearance PBRAppearance {
                              baseColor 0.1 0.1 0.1
                              roughness 1
                              metalness 0
                            }
                            geometry Box {
                              size 0.45 0.01 0.4
                            }
                          }
                        ]
                      }
                    ]
                  }
                  DEF RIGHT_ARM Transform {
                    translation 0 0 0.32
                    rotation -4.79489e-09 1 4.79489e-09 -1.5707953071795862
                    children [
                      Shape {
                        appearance PBRAppearance {
                          baseColor 0.8 0.8 0.8
                          roughness 1
                          metalness 0
                          name "DefaultMaterial"
                        }
                        geometry Mesh {
                          url [
                            "meshes/ET3116A_rightarm.STL"
                          ]
                        }
                      }
                      Transform {
                        translation 0.41 0 0.53
                        rotation 1 0 0 1.5708003061004252
                        children [
                          Shape {
                            appearance PBRAppearance {
                              baseColor 0.1 0.1 0.1
                              roughness 1
                              metalness 0
                            }
                            geometry Cylinder {
                              height 0.01
                              radius 0.2
                            }
                          }
                        ]
                      }
                      Transform {
                        translation 0.41 0 -0.53
                        rotation 1 0 0 1.5708003061004252
                        children [
                          Shape {
                            appearance PBRAppearance {
                              baseColor 0.1 0.1 0.1
                              roughness 1
                              metalness 0
                            }
                            geometry Cylinder {
                              height 0.01
                              radius 0.2
                            }
                          }
                          Shape {
                            appearance PBRAppearance {
                              baseColor 1 0 0
                            }
                            geometry Box {
                              size 0.1 0.05 0.1
                            }
                          }
                        ]
                      }
                    ]
                  }
                  DEF LOAD_EXTENSION_SLOT Group {
                    children IS loadExtensionSlot
                  }
                ]
                boundingObject Group {
                  children [
                    Transform {
                      translation 0 0 -0.84
                      rotation 0 1 0 1.5708
                      children [
                        Box {
                          size 0.5 0.5 1
                        }
                      ]
                    }
                    Transform {
                      translation 0 0 0.73
                      rotation 0 1 0 1.5708
                      children [
                        Shape {
                          geometry Box {
                            size 0.5 0.5 1
                          }
                        }
                      ]
                    }
                  ]
                }
              }
            }
          ]
        }
      }
    ]
  }
}